<?xml version="1.0" ?>
<!-- =================================================================================== -->
<!-- |    This document was autogenerated by xacro from /home/plancaster/gum_ws/install/meta_hand_description/share/meta_hand_description/robots/meta_hand.urdf.xacro | -->
<!-- |    EDITING THIS FILE BY HAND IS NOT RECOMMENDED                                 | -->
<!-- =================================================================================== -->
<robot name="meta_hand">
  <!--0.002298-->
  <!-- Adapted from https://github.com/simlabrobotics/allegro_hand_ros/blob/master/allegro_hand_description/allegro_hand_description_left.xacro -->
  <!-- ======================== FINGER PARAMS ======================== -->
  <!-- ========================= THUMB PARAMS ========================= -->
  <!-- ========================= LIMITS ========================= -->
  <!-- ============================================================================= -->
  <!-- ============================================================================= -->
  <!-- ============================================================================= -->
  <!-- END THUMB MACRO -->
  <!-- [[END]] THREE FINGER MACRO -->
  <!-- ============================================================================= -->
  <!-- ============================================================================= -->
  <!-- ============================================================================= -->
  <!-- BASE -->
  <link name="base_link">
    <visual>
      <geometry>
        <mesh filename="./meshes/base_link.obj"/>
      </geometry>
      <origin rpy="0 0 0" xyz="0 0 0 "/>
      <material name="black">
        <color rgba="0.2 0.2 0.2 1"/>
      </material>
    </visual>
    <collision>
      <origin rpy="0 0 0" xyz="-0.009300 0 -0.0475"/>
      <geometry>
        <!-- <box size="0.0408 0.1130 0.095"/> -->
        <box size="0.03 0.07 0.07"/>
      </geometry>
    </collision>
    <inertial>
      <origin rpy="0 0 0" xyz="0 0 0.0475"/>
      <mass value="0.4154"/>
      <inertia ixx="1e-4" ixy="0.0" ixz="0.0" iyy="1e-4" iyz="0.0" izz="1e-4"/>
    </inertial>
  </link>
  <link name="palm_reskin_link">
    <visual>
      <geometry>
        <mesh filename="./meshes/reskin_palm_pad.obj" scale="0.001 0.001 0.001"/>
      </geometry>
      <origin rpy="1.5707963259 0 1.5707963259" xyz="0 0 0 "/>
      <material name="grey">
        <color rgba="0.4 0.4 0.4 1"/>
      </material>
    </visual>
    <collision>
     <geometry>
        <mesh filename="./meshes/reskin_palm_pad.obj" scale="0.001 0.001 0.001"/>
      </geometry>
      <origin rpy="1.5707963259 0 1.5707963259" xyz="0 0 0"/>
    </collision>
  </link>
  <joint name="palm_reskin_joint" type="fixed">
    <parent link="base_link"/>
    <child link="palm_reskin_link"/>
    <!-- <origin rpy="0 0 0" xyz="0.0175 -0.0457 -0.041"/> -->
    <origin rpy="0 0 0" xyz="0.014 -0.0457 -0.041"/>
  </joint>
  <!-- [LINK 0, 4, 8] -->
  <link name="link_0.0">
    <visual>
      <geometry>
        <mesh filename="./meshes/link_0.0.obj"/>
      </geometry>
      <material name="black">
        <color rgba=".2 .2 .2 1"/>
      </material>
    </visual>
    <collision>
      <geometry>
        <box size="0.0196 0.0275 0.0164"/>
      </geometry>
      <origin rpy="0 0 0" xyz="0 0 0.0082"/>
    </collision>
    <inertial>
      <mass value="0.0119"/>
      <origin rpy="0 0 0" xyz="0 0 0"/>
      <inertia ixx="1.01666658333e-06" ixy="0.0" ixz="0.0" iyy="6.47677333333e-07" iyz="0.0" izz="1.01666658333e-06"/>
    </inertial>
  </link>
  <joint name="joint_0.0" type="revolute">
    <axis xyz="0 0 1"/>
    <limit effort="0.35" lower="-0.582" upper="0.547" velocity="6.283"/>
    <parent link="base_link"/>
    <child link="link_0.0"/>
    <origin rpy="-0.08726646254999999 0 0" xyz="0 0.0435 -0.001542"/>
  </joint>
  <!-- [LINK 1, 5, 9] -->
  <link name="link_1.0">
    <visual>
      <geometry>
        <mesh filename="./meshes/link_1.0.obj"/>
      </geometry>
      <material name="black">
        <color rgba=".2 .2 .2 1"/>
      </material>
    </visual>
    <collision>
      <geometry>
        <box size="0.0196 0.0275 0.054"/>
      </geometry>
      <origin rpy="0 0 0" xyz="0 0 0.027"/>
    </collision>
    <inertial>
      <mass value="0.065"/>
      <origin rpy="0 0 0" xyz="0 0 0"/>
      <inertia ixx="7.95654166667e-05" ixy="1.7199e-05" ixz="8.75875e-06" iyy="2.47088833333e-05" iyz="2.413125e-05" izz="7.95654166667e-05"/>
    </inertial>
  </link>
  <joint name="joint_1.0" type="revolute">
    <limit effort="0.35" lower="-0.261" upper="1.734" velocity="6.283"/>
    <axis xyz="0 1 0"/>
    <parent link="link_0.0"/>
    <child link="link_1.0"/>
    <origin xyz="0 0 0.0164"/>
  </joint>
  <!-- [LINK 2, 6, 10]-->
  <link name="link_2.0">
    <visual>
      <geometry>
        <mesh filename="./meshes/link_2.0.obj"/>
      </geometry>
      <material name="black">
        <color rgba=".2 .2 .2 1"/>
      </material>
    </visual>
    <collision>
      <geometry>
        <box size="0.0196 0.0275 0.0384"/>
      </geometry>
      <origin rpy="0 0 0" xyz="0 0 0.0192"/>
    </collision>
    <inertial>
      <mass value="0.0355"/>
      <origin rpy="0 0 0" xyz="0 0 0"/>
      <inertia ixx="2.63979183333e-05" ixy="6.67968e-06" ixz="4.783625e-06" iyy="1.34948516667e-05" iyz="9.372e-06" izz="2.63979183333e-05"/>
    </inertial>
  </link>
  <joint name="joint_2.0" type="revolute">
    <axis xyz="0 1 0"/>
    <limit effort="0.35" lower="-0.271" upper="1.727825" velocity="6.283"/>
    <parent link="link_1.0"/>
    <child link="link_2.0"/>
    <origin xyz="0 0 0.054"/>
  </joint>
  <!-- [LINK 3, 7, 11] -->
  <link name="link_3.0">
    <visual>
      <geometry>
        <mesh filename="./meshes/link_3.0.obj"/>
      </geometry>
      <material name="black">
        <color rgba=".2 .2 .2 1"/>
      </material>
    </visual>
    <collision>
      <geometry>
        <sphere radius="0.0001"/>
      </geometry>
      <origin rpy="0 0 0" xyz="0 0 0.013349999999999999"/>
    </collision>
    <inertial>
      <mass value="0.0096"/>
      <origin rpy="0 0 0" xyz="0 0 0"/>
      <inertia ixx="4.701248e-06" ixy="1.255968e-06" ixz="1.2936e-06" iyy="3.649312e-06" iyz="1.7622e-06" izz="4.701248e-06"/>
    </inertial>
  </link>
  <joint name="joint_3.0" type="revolute">
    <axis xyz="0 1 0"/>
    <limit effort="0.35" lower="-0.281" upper="1.727825" velocity="6.283"/>
    <parent link="link_2.0"/>
    <child link="link_3.0"/>
    <origin xyz="0 0 0.0384"/>
  </joint>
  <!-- [FINGER TIP] -->
  
  <link name="link_3.0_tip">
    <visual>
      <geometry>
        <mesh filename="./meshes/digit.obj"/>
      </geometry>
      <material name="white">
        <color rgba=".9 .9 .9 1"/>
      </material>
    </visual>
    <collision>
      <geometry>
        <mesh filename="./meshes/digit.obj"/>
      </geometry>
      <!-- <origin rpy="0 0 0" xyz="0 0 0"/> -->
      <!-- <origin rpy="0 0 0" xyz="0.0036695246 0.0000277434 0.0124368531"/> -->
    </collision>
    <inertial>
      <mass value="0.0168"/>
      <!-- <origin rpy="0 0 0" xyz="0 0 0"/> -->
      <origin rpy="0 0 0" xyz="0 0 0.0147"/>
      <inertia ixx="9.68e-07" ixy="0" ixz="0" iyy="9.68e-07" iyz="0" izz="9.68e-07"/>
    </inertial>
  </link>
  <joint name="joint_3_tip" type="fixed">
    <parent link="link_3.0"/>
    <child link="link_3.0_tip"/>
    <!-- <origin rpy="0 0 -1.5707963259" xyz="0 0 0.0147"/> -->
    <origin rpy="0 0 0" xyz="0 0 0.0147"/>
    </joint>
  <link name="digit_fingertip_3.0">
    <visual>
       <geometry>
       	   <mesh filename="./meshes/digit_v1_fingertip_pad.obj"/>
       </geometry>
       <material name="blue">
          <color rgba="0 0 1 1" />
       </material>
    </visual>
    <collision>
    	<geometry>
            <mesh filename="./meshes/digit_v1_fingertip_pad.obj"/>
      </geometry>
    </collision>
    <inertial>
      <mass value="0.0168"/>
      <!-- <origin rpy="0 0 0" xyz="0 0 0"/> -->
      <origin rpy="0 0 0" xyz="0 0 0"/>
      <inertia ixx="9.68e-07" ixy="0" ixz="0" iyy="9.68e-07" iyz="0" izz="9.68e-07"/>
    </inertial>
  </link>
  <joint name="joint_3.0_digit_fingertip" type="fixed">
    <parent link="link_3.0_tip"/>
    <child link="digit_fingertip_3.0"/>
    <origin rpy="0 0 0" xyz="0.0005 -0.009 0.0"/>
  </joint>
 
  <link name="reskin_link_1.0a">
    <!-- <visual>
      <geometry>
        <mesh filename="./meshes/reskin_finger_pad.obj" scale="0.001 0.001 0.001"/>
      </geometry>
      <origin rpy="-1.5707963259 0 -1.5707963259" xyz="0 0 0"/>
      <material name="grey">
        <color rgba="0.4 0.4 0.4 1"/>
      </material>
    </visual> -->
      <!-- <collision>
      <geometry>
         <mesh filename="./meshes/reskin_finger_pad.obj" scale="0.001 0.001 0.03"/>
      </geometry>
      <origin rpy="-1.5707963259 0 -1.5707963259" xyz="0 0 0"/>
    </collision> -->
  </link>
  <joint name="reskin_joint_1a" type="fixed">
    <parent link="link_1.0"/>
    <child link="reskin_link_1.0a"/>
    <origin rpy="0 0 0" xyz="0.0118 0.009 0.022"/>
  </joint>
  <link name="reskin_link_1.0b">
    <!-- <visual>
      <geometry>
        <mesh filename="./meshes/reskin_finger_pad.obj" scale="0.001 0.001 0.001"/>
      </geometry>
      <origin rpy="-1.5707963259 0 -1.5707963259" xyz="0 0 0"/>
      <material name="grey">
        <color rgba="0.4 0.4 0.4 1"/>
      </material>
    </visual> -->
    <!-- <collision>
    <geometry>
        <mesh filename="./meshes/reskin_finger_pad.obj" scale="0.001 0.001 0.03"/>
      </geometry>
      <origin rpy="-1.5707963259 0 -1.5707963259" xyz="0 0 0"/>
    </collision> -->
  </link>
  <joint name="reskin_joint_1b" type="fixed">
    <parent link="link_1.0"/>
    <child link="reskin_link_1.0b"/>
    <origin rpy="0 0 0" xyz="0.0118 0.009 0.053"/>
  </joint>
  <link name="reskin_link_2.0">
    <!-- <visual>
      <geometry>
        <mesh filename="./meshes/reskin_finger_pad.obj" scale="0.001 0.001 0.001"/>
      </geometry>
      <origin rpy="-1.5707963259 0 -1.5707963259" xyz="0 0 0"/>
      <material name="grey">
        <color rgba="0.4 0.4 0.4 1"/>
      </material>
    </visual> -->
    <!-- <collision>
    <geometry>
        <mesh filename="./meshes/reskin_finger_pad.obj" scale="0.001 0.001 0.03"/>
      </geometry>
      <origin rpy="-1.5707963259 0 -1.5707963259" xyz="0 0 0"/>
    </collision> -->
  </link>
  <joint name="reskin_joint_2" type="fixed">
    <parent link="link_2.0"/>
    <child link="reskin_link_2.0"/>
    <origin rpy="0 0 0" xyz="0.0118 0.009 0.0375"/>
  </joint>
  <!-- [LINK 0, 4, 8] -->
  <link name="link_4.0">
    <visual>
      <geometry>
        <mesh filename="./meshes/link_0.0.obj"/>
      </geometry>
      <material name="black">
        <color rgba=".2 .2 .2 1"/>
      </material>
    </visual>
    <collision>
      <geometry>
        <box size="0.0196 0.0275 0.0164"/>
      </geometry>
      <origin rpy="0 0 0" xyz="0 0 0.0082"/>
    </collision>
    <inertial>
      <mass value="0.0119"/>
      <origin rpy="0 0 0" xyz="0 0 0"/>
      <inertia ixx="1.01666658333e-06" ixy="0.0" ixz="0.0" iyy="6.47677333333e-07" iyz="0.0" izz="1.01666658333e-06"/>
    </inertial>
  </link>
  <joint name="joint_4.0" type="revolute">
    <axis xyz="0 0 1"/>
    <limit effort="0.35" lower="-0.581" upper="0.560" velocity="6.283"/>
    <parent link="base_link"/>
    <child link="link_4.0"/>
    <origin rpy="0.0 0 0" xyz="0 0 0.0007"/>
  </joint>
  <!-- [LINK 1, 5, 9] -->
  <link name="link_5.0">
    <visual>
      <geometry>
        <mesh filename="./meshes/link_1.0.obj"/>
      </geometry>
      <material name="black">
        <color rgba=".2 .2 .2 1"/>
      </material>
    </visual>
    <collision>
      <geometry>
        <box size="0.0196 0.0275 0.054"/>
      </geometry>
      <origin rpy="0 0 0" xyz="0 0 0.027"/>
    </collision>
    <inertial>
      <mass value="0.065"/>
      <origin rpy="0 0 0" xyz="0 0 0"/>
      <inertia ixx="7.95654166667e-05" ixy="1.7199e-05" ixz="8.75875e-06" iyy="2.47088833333e-05" iyz="2.413125e-05" izz="7.95654166667e-05"/>
    </inertial>
  </link>
  <joint name="joint_5.0" type="revolute">
    <limit effort="0.35" lower="-0.260" upper="1.7703" velocity="6.283"/>
    <axis xyz="0 1 0"/>
    <parent link="link_4.0"/>
    <child link="link_5.0"/>
    <origin xyz="0 0 0.0164"/>
  </joint>
  <!-- [LINK 2, 6, 10]-->
  <link name="link_6.0">
    <visual>
      <geometry>
        <mesh filename="./meshes/link_2.0.obj"/>
      </geometry>
      <material name="black">
        <color rgba=".2 .2 .2 1"/>
      </material>
    </visual>
    <collision>
      <geometry>
        <box size="0.0196 0.0275 0.0384"/>
      </geometry>
      <origin rpy="0 0 0" xyz="0 0 0.0192"/>
    </collision>
    <inertial>
      <mass value="0.0355"/>
      <origin rpy="0 0 0" xyz="0 0 0"/>
      <inertia ixx="2.63979183333e-05" ixy="6.67968e-06" ixz="4.783625e-06" iyy="1.34948516667e-05" iyz="9.372e-06" izz="2.63979183333e-05"/>
    </inertial>
  </link>
  <joint name="joint_6.0" type="revolute">
    <axis xyz="0 1 0"/>
    <limit effort="0.35" lower="-0.305" upper="1.296" velocity="6.283"/>
    <parent link="link_5.0"/>
    <child link="link_6.0"/>
    <origin xyz="0 0 0.054"/>
  </joint>
  <!-- [LINK 3, 7, 11] -->
  <link name="link_7.0">
    <visual>
      <geometry>
        <mesh filename="./meshes/link_3.0.obj"/>
      </geometry>
      <material name="black">
        <color rgba=".2 .2 .2 1"/>
      </material>
    </visual>
    <collision>
      <geometry>
        <sphere radius="0.0001"/>
      </geometry>
      <origin rpy="0 0 0" xyz="0 0 0.013349999999999999"/>
    </collision>
    <inertial>
      <mass value="0.0096"/>
      <origin rpy="0 0 0" xyz="0 0 0"/>
      <inertia ixx="4.701248e-06" ixy="1.255968e-06" ixz="1.2936e-06" iyy="3.649312e-06" iyz="1.7622e-06" izz="4.701248e-06"/>
    </inertial>
  </link>
  <joint name="joint_7.0" type="revolute">
    <axis xyz="0 1 0"/>
    <limit effort="0.35" lower="-0.3047" upper="1.176" velocity="6.283"/>
    <parent link="link_6.0"/>
    <child link="link_7.0"/>
    <origin xyz="0 0 0.0384"/>
  </joint>
  <!-- [FINGER TIP] -->
  <link name="link_7.0_tip">
    <visual>
      <geometry>
        <mesh filename="./meshes/digit.obj"/>
      </geometry>
      <material name="white">
        <color rgba=".9 .9 .9 1"/>
      </material>
    </visual>
    <collision>
      <geometry>
        <mesh filename="./meshes/digit.obj"/>
      </geometry>
      <origin rpy="0 0 0" xyz="0 0 0"/>
      <!-- <origin rpy="0 0 0" xyz="0.0036695246 0.0000277434 0.0124368531"/> -->
    </collision>
    <inertial>
      <mass value="0.0168"/>
      <!-- <origin rpy="0 0 0" xyz="0 0 0"/> -->
      <origin rpy="0 0 0" xyz="0 0 0.0147"/>
      <inertia ixx="9.68e-07" ixy="0" ixz="0" iyy="9.68e-07" iyz="0" izz="9.68e-07"/>
    </inertial>
  </link>
  <joint name="joint_7_tip" type="fixed">
    <parent link="link_7.0"/>
    <child link="link_7.0_tip"/>
    <origin rpy="0 0 0" xyz="0 0 0.0147"/>
  </joint>
    <link name="digit_fingertip_7.0">
    <visual>
       <geometry>
       	   <mesh filename="./meshes/digit_v1_fingertip_pad.obj"/>
       </geometry>
       <material name="blue">
          <color rgba="0 0 1 1" />
       </material>
    </visual>
    <collision>
    	<geometry>
            <mesh filename="./meshes/digit_v1_fingertip_pad.obj"/>
      </geometry>
    </collision>
    <inertial>
      <mass value="0.0168"/>
      <!-- <origin rpy="0 0 0" xyz="0 0 0"/> -->
      <origin rpy="0 0 0" xyz="0 0 0"/>
      <inertia ixx="9.68e-07" ixy="0" ixz="0" iyy="9.68e-07" iyz="0" izz="9.68e-07"/>
    </inertial>
  </link>
  <joint name="joint_7.0_digit_fingertip" type="fixed">
    <parent link="link_7.0_tip"/>
    <child link="digit_fingertip_7.0"/>
    <origin rpy="0 0 0" xyz="0.0005 -0.009 0.0"/>
  </joint>
  <link name="reskin_link_5.0a">
    <!-- <visual>
      <geometry>
        <mesh filename="./meshes/reskin_finger_pad.obj" scale="0.001 0.001 0.001"/>
      </geometry>
      <origin rpy="-1.5707963259 0 -1.5707963259" xyz="0 0 0"/>
      <material name="grey">
        <color rgba="0.4 0.4 0.4 1"/>
      </material>
    </visual> -->
    <!-- <collision>
    <geometry>
        <mesh filename="./meshes/reskin_finger_pad.obj" scale="0.001 0.001 0.03"/>
      </geometry>
      <origin rpy="-1.5707963259 0 -1.5707963259" xyz="0 0 0"/>
    </collision> -->
  </link>
  <joint name="reskin_joint_5a" type="fixed">
    <parent link="link_5.0"/>
    <child link="reskin_link_5.0a"/>
    <origin rpy="0 0 0" xyz="0.0118 0.009 0.022"/>
  </joint>
  <link name="reskin_link_5.0b">
    <!-- <visual>
      <geometry>
        <mesh filename="./meshes/reskin_finger_pad.obj" scale="0.001 0.001 0.001"/>
      </geometry>
      <origin rpy="-1.5707963259 0 -1.5707963259" xyz="0 0 0"/>
      <material name="grey">
        <color rgba="0.4 0.4 0.4 1"/>
      </material>
    </visual> -->
    <!-- <collision>
    <geometry>
        <mesh filename="./meshes/reskin_finger_pad.obj" scale="0.001 0.001 0.03"/>
      </geometry>
      <origin rpy="-1.5707963259 0 -1.5707963259" xyz="0 0 0"/>
    </collision> -->
  </link>
  <joint name="reskin_joint_5b" type="fixed">
    <parent link="link_5.0"/>
    <child link="reskin_link_5.0b"/>
    <origin rpy="0 0 0" xyz="0.0118 0.009 0.053"/>
  </joint>
  <link name="reskin_link_6.0">
    <!-- <visual>
      <geometry>
        <mesh filename="./meshes/reskin_finger_pad.obj" scale="0.001 0.001 0.001"/>
      </geometry>
      <origin rpy="-1.5707963259 0 -1.5707963259" xyz="0 0 0"/>
      <material name="grey">
        <color rgba="0.4 0.4 0.4 1"/>
      </material>
    </visual> -->
    <!-- <collision>
        <geometry>
        <mesh filename="./meshes/reskin_finger_pad.obj" scale="0.001 0.001 0.03"/>
        </geometry>
      <origin rpy="-1.5707963259 0 -1.5707963259" xyz="0 0 0"/>
    </collision> -->
  </link>
  <joint name="reskin_joint_6" type="fixed">
    <parent link="link_6.0"/>
    <child link="reskin_link_6.0"/>
    <origin rpy="0 0 0" xyz="0.0118 0.009 0.0375"/>
  </joint>
  <!-- [LINK 0, 4, 8] -->
  <link name="link_8.0">
    <visual>
      <geometry>
        <mesh filename="./meshes/link_0.0.obj"/>
      </geometry>
      <material name="black">
        <color rgba=".2 .2 .2 1"/>
      </material>
    </visual>
    <collision>
      <geometry>
        <box size="0.0196 0.0275 0.0164"/>
      </geometry>
      <origin rpy="0 0 0" xyz="0 0 0.0082"/>
    </collision>
    <inertial>
      <mass value="0.0119"/>
      <origin rpy="0 0 0" xyz="0 0 0"/>
      <inertia ixx="1.01666658333e-06" ixy="0.0" ixz="0.0" iyy="6.47677333333e-07" iyz="0.0" izz="1.01666658333e-06"/>
    </inertial>
  </link>
  <joint name="joint_8.0" type="revolute">
    <axis xyz="0 0 1"/>
    <limit effort="0.35" lower="-0.584" upper="0.554" velocity="6.283"/>
    <parent link="base_link"/>
    <child link="link_8.0"/>
    <origin rpy="0.08726646254999999 0 0" xyz="0 -0.0435 -0.001542"/>
  </joint>
  <!-- [LINK 1, 5, 9] -->
  <link name="link_9.0">
    <visual>
      <geometry>
        <mesh filename="./meshes/link_1.0.obj"/>
      </geometry>
      <material name="black">
        <color rgba=".2 .2 .2 1"/>
      </material>
    </visual>
    <collision>
      <geometry>
        <box size="0.0196 0.0275 0.054"/>
      </geometry>
      <origin rpy="0 0 0" xyz="0 0 0.027"/>
    </collision>
    <inertial>
      <mass value="0.065"/>
      <origin rpy="0 0 0" xyz="0 0 0"/>
      <inertia ixx="7.95654166667e-05" ixy="1.7199e-05" ixz="8.75875e-06" iyy="2.47088833333e-05" iyz="2.413125e-05" izz="7.95654166667e-05"/>
    </inertial>
  </link>
  <joint name="joint_9.0" type="revolute">
    <limit effort="0.35" lower="-0.257" upper="1.752" velocity="6.283"/>
    <axis xyz="0 1 0"/>
    <parent link="link_8.0"/>
    <child link="link_9.0"/>
    <origin xyz="0 0 0.0164"/>
  </joint>
  <!-- [LINK 2, 6, 10]-->
  <link name="link_10.0">
    <visual>
      <geometry>
        <mesh filename="./meshes/link_2.0.obj"/>
      </geometry>
      <material name="black">
        <color rgba=".2 .2 .2 1"/>
      </material>
    </visual>
    <collision>
      <geometry>
        <box size="0.0196 0.0275 0.0384"/>
      </geometry>
      <origin rpy="0 0 0" xyz="0 0 0.0192"/>
    </collision>
    <inertial>
      <mass value="0.0355"/>
      <origin rpy="0 0 0" xyz="0 0 0"/>
      <inertia ixx="2.63979183333e-05" ixy="6.67968e-06" ixz="4.783625e-06" iyy="1.34948516667e-05" iyz="9.372e-06" izz="2.63979183333e-05"/>
    </inertial>
  </link>
  <joint name="joint_10.0" type="revolute">
    <axis xyz="0 1 0"/>
    <limit effort="0.35" lower="-0.263" upper="1.346" velocity="6.283"/>
    <parent link="link_9.0"/>
    <child link="link_10.0"/>
    <origin xyz="0 0 0.054"/>
  </joint>
  <!-- [LINK 3, 7, 11] -->
  <link name="link_11.0">
    <visual>
      <geometry>
        <mesh filename="./meshes/link_3.0.obj"/>
      </geometry>
      <material name="black">
        <color rgba=".2 .2 .2 1"/>
      </material>
    </visual>
    <collision>
      <geometry>
        <sphere radius="0.0001"/>
      </geometry>
      <origin rpy="0 0 0" xyz="0 0 0.013349999999999999"/>
    </collision>
    <inertial>
      <mass value="0.0096"/>
      <origin rpy="0 0 0" xyz="0 0 0"/>
      <inertia ixx="4.701248e-06" ixy="1.255968e-06" ixz="1.2936e-06" iyy="3.649312e-06" iyz="1.7622e-06" izz="4.701248e-06"/>
    </inertial>
  </link>
  <joint name="joint_11.0" type="revolute">
    <axis xyz="0 1 0"/>
    <limit effort="0.35" lower="-0.284" upper="1.170" velocity="6.283"/>
    <parent link="link_10.0"/>
    <child link="link_11.0"/>
    <origin xyz="0 0 0.0384"/>
  </joint>
  <!-- [FINGER TIP] -->
  <link name="link_11.0_tip">
    <visual>
      <geometry>
        <mesh filename="./meshes/digit.obj"/>
      </geometry>
      <material name="white">
        <color rgba=".9 .9 .9 1"/>
      </material>
    </visual>
    <collision>
      <geometry>
       <mesh filename="./meshes/digit.obj"/>
      </geometry>
      <origin rpy="0 0 0" xyz="0 0 0"/>
      <origin rpy="0 0 0" xyz="0.0036695246 0.0000277434 0.0124368531"/> 
      <origin rpy="0 0 0" xyz="0 0 0"/>
    </collision> 
    <inertial>
      <mass value="0.0168"/>
      <!-- <origin rpy="0 0 0" xyz="0 0 0"/> -->
      
      <inertia ixx="9.68e-07" ixy="0" ixz="0" iyy="9.68e-07" iyz="0" izz="9.68e-07"/>
    </inertial>
  </link>
  <joint name="joint_11_tip" type="fixed">
    <parent link="link_11.0"/>
    <child link="link_11.0_tip"/>
    <!-- <origin rpy="0 0 1.5707963259" xyz="0 0 0.0147"/> -->
    <origin rpy="0 0 0" xyz="0 0 0.0147"/>
  </joint>

  <link name="digit_fingertip_11.0">
    <visual>
       <geometry>
       	   <mesh filename="./meshes/digit_v1_fingertip_pad.obj"/>
       </geometry>
       <material name="blue">
          <color rgba="0 0 1 1" />
       </material>
    </visual>
    <collision>
    	<geometry>
            <mesh filename="./meshes/digit_v1_fingertip_pad.obj"/>
      </geometry>
      
    </collision>
    <inertial>
      <mass value="0.0168"/>
      <!-- <origin rpy="0 0 0" xyz="0 0 0"/> -->
      <origin rpy="0 0 0" xyz="0 0 0"/>
      <inertia ixx="9.68e-07" ixy="0" ixz="0" iyy="9.68e-07" iyz="0" izz="9.68e-07"/>
    </inertial>
  </link>
  <joint name="joint_11.0_digit_fingertip" type="fixed">
    <parent link="link_11.0"/>
    <child link="digit_fingertip_11.0"/>
    <origin rpy="0 0 0" xyz="0.0005 -0.009 0.0147"/>
  </joint>

  <link name="reskin_link_9.0a">
    <!-- <visual>
      <geometry>
        <mesh filename="./meshes/reskin_finger_pad.obj" scale="0.001 0.001 0.001"/>
      </geometry>
      <origin rpy="-1.5707963259 0 -1.5707963259" xyz="0 0 0"/>
      <material name="grey">
        <color rgba="0.4 0.4 0.4 1"/>
      </material>
    </visual> -->
    <!-- <collision>
    <geometry>
        <mesh filename="./meshes/reskin_finger_pad.obj" scale="0.001 0.001 0.03"/>
      </geometry>
      <origin rpy="-1.5707963259 0 -1.5707963259" xyz="0 0 0"/>
    </collision> -->
  </link>
  <joint name="reskin_joint_9a" type="fixed">
    <parent link="link_9.0"/>
    <child link="reskin_link_9.0a"/>
    <origin rpy="0 0 0" xyz="0.0118 0.009 0.022"/>
  </joint>
  <link name="reskin_link_9.0b">
    <!-- <visual>
      <geometry>
        <mesh filename="./meshes/reskin_finger_pad.obj" scale="0.001 0.001 0.001"/>
      </geometry>
      <origin rpy="-1.5707963259 0 -1.5707963259" xyz="0 0 0"/>
      <material name="grey">
        <color rgba="0.4 0.4 0.4 1"/>
      </material>
    </visual> -->
    <!-- <collision>
    <geometry>
        <mesh filename="./meshes/reskin_finger_pad.obj" scale="0.001 0.001 0.03"/>
      </geometry>
      <origin rpy="-1.5707963259 0 -1.5707963259" xyz="0 0 0"/>
    </collision> -->
  </link>
  <joint name="reskin_joint_9b" type="fixed">
    <parent link="link_9.0"/>
    <child link="reskin_link_9.0b"/>
    <origin rpy="0 0 0" xyz="0.0118 0.009 0.053"/>
  </joint>
  <link name="reskin_link_10.0">
    <!-- <visual>
      <geometry>
        <mesh filename="./meshes/reskin_finger_pad.obj" scale="0.001 0.001 0.001"/>
      </geometry>
      <origin rpy="-1.5707963259 0 -1.5707963259" xyz="0 0 0"/>
      <material name="grey">
        <color rgba="0.4 0.4 0.4 1"/>
      </material>
    </visual> -->
    <!-- <collision>
      <geometry>
        <mesh filename="./meshes/reskin_finger_pad.obj" scale="0.001 0.001 0.03"/>
      </geometry>
      <origin rpy="-1.5707963259 0 -1.5707963259" xyz="0 0 0"/>
    </collision> -->
  </link>
  <joint name="reskin_joint_10" type="fixed">
    <parent link="link_10.0"/>
    <child link="reskin_link_10.0"/>
    <origin rpy="0 0 0" xyz="0.0118 0.009 0.0375"/>
  </joint>
  <!-- [LINK 12] -->
  <link name="link_12.0">
    <visual>
      <geometry>
        <mesh filename="./meshes/link_12.0_right.obj"/>
      </geometry>
      <material name="black">
        <color rgba=".2 .2 .2 1"/>
      </material>
    </visual>
    <collision>
      <geometry>
        <box size="0.0358 0.034 0.0455"/>
      </geometry>
      <origin rpy="0 0 0" xyz="-0.0179 0.009 0.0145"/>
    </collision>
    <inertial>
      <mass value="0.0176"/>
      <origin rpy="0 0 0" xyz="0 0 0"/>
      <inertia ixx="1.89273333333e-5" ixy="7.16716e-06" ixz="5.35568e-06" iyy="1.43008213333e-05" iyz="6.8068e-06" izz="1.89273333333e-05"/>
    </inertial>
  </link>
  <joint name="joint_12.0" type="revolute">
    <axis xyz="-1 0 0"/>
    <limit effort="0.35" lower="0.254" upper="1.5616" velocity="6.283"/>
    <parent link="base_link"/>
    <child link="link_12.0"/>
    <origin rpy="0 -1.6580627884499999 -1.5707963259" xyz="-0.0182 0.019333 -0.045987"/>
  </joint>
  <!-- [LINK 13] -->
  <link name="link_13.0">
    <visual>
      <geometry>
        <mesh filename="./meshes/link_13.0.obj"/>
      </geometry>
      <material name="black">
        <color rgba=".2 .2 .2 1"/>
      </material>
    </visual>
    <collision>
      <geometry>
        <box size="0.0196 0.0275 0.0177"/>
      </geometry>
      <origin rpy="0 0 0" xyz="0 0 0.00885"/>
    </collision>
    <inertial>
      <mass value="0.0119"/>
      <origin rpy="0 0 0" xyz="0 0 0"/>
      <inertia ixx="4.24250866667e-06" ixy="1.032087e-06" ixz="1.603525e-06" iyy="4.52362633333e-06" iyz="1.44808125e-06" izz="4.24250866667e-06"/>
    </inertial>
  </link>
  <joint name="joint_13.0" type="revolute">
    <axis xyz="0 0 1"/>
    <limit effort="0.35" lower="-0.343" upper="1.167" velocity="6.283"/>
    <parent link="link_12.0"/>
    <child link="link_13.0"/>
    <origin xyz="-0.027 0.005 0.0399"/>
  </joint>
  <!-- [LINK 14] -->
  <link name="link_14.0">
    <visual>
      <geometry>
        <mesh filename="./meshes/link_14.0.obj"/>
      </geometry>
      <material name="black">
        <color rgba=".2 .2 .2 1"/>
      </material>
    </visual>
    <collision>
      <geometry>
        <box size="0.0196 0.0275 0.0514"/>
      </geometry>
      <origin rpy="0 0 0" xyz="0 0 0.0257"/>
    </collision>
    <inertial>
      <mass value="0.038"/>
      <origin rpy="0 0 0" xyz="0 0 0"/>
      <inertia ixx="4.30439933333e-05" ixy="9.57068e-06" ixz="5.1205e-06" iyy="1.44451933333e-05" iyz="1.342825e-05" izz="4.30439933333e-05"/>
    </inertial>
  </link>
  <joint name="joint_14.0" type="revolute">
    <axis xyz="0 1 0"/>
    <limit effort="0.35" lower="-0.239" upper="1.055" velocity="6.238"/>
    <parent link="link_13.0"/>
    <child link="link_14.0"/>
    <origin xyz="0 0 0.0177"/>
  </joint>
  <!-- [LINK 15] -->
  <link name="link_15.0">
    <visual>
      <geometry>
        <mesh filename="./meshes/link_15.0.obj"/>
      </geometry>
      <material name="black">
        <color rgba=".2 .2 .2 1"/>
      </material>
    </visual>
    <collision>
      <geometry>
        <sphere radius="0.0001"/>
      </geometry>
      <origin rpy="0 0 0" xyz="0 0 0.021150000000000002"/>
    </collision>
    <inertial>
      <mass value="0.0388"/>
      <origin rpy="0 0 0" xyz="0 0 0"/>
      <inertia ixx="3.29223173333e-05" ixy="8.042076e-06" ixz="5.2283e-06" iyy="1.47493026667e-5" iyz="1.1283525e-5" izz="3.29223173333e-05"/>
    </inertial>
  </link>
  <joint name="joint_15.0" type="revolute">
    <axis xyz="0 1 0"/>
    <limit effort="0.35" lower="-0.262" upper="1.783" velocity="6.238"/>
    <parent link="link_14.0"/>
    <child link="link_15.0"/>
    <origin xyz="0 0 0.0514"/>
  </joint>
  <!-- [FINGER TIP] -->
  <link name="link_15.0_tip">
    <visual>
      <geometry>
        <mesh filename="./meshes/digit.obj"/>
      </geometry>
      <material name="white">
        <color rgba=".9 .9 .9 1"/>
      </material>
    </visual>
    <collision>
      <geometry>
        <mesh filename="./meshes/digit.obj"/>
      </geometry>
      <!-- <origin rpy="0 0 0" xyz="0 0 0"/>
      <origin rpy="0 0 0" xyz="0.0036695246 0.0000277434 0.0124368531"/> -->
    </collision>
  </link>
  <joint name="joint_15_tip" type="fixed">
    <parent link="link_15.0"/>
    <child link="link_15.0_tip"/>
    <!-- <origin rpy="0 0 -1.0471975506" xyz="0 0 0.0303"/> -->
    <origin rpy="0 0 0" xyz="0 0 0.0303"/>
  </joint>
  <link name="digit_fingertip_15.0">
    <visual>
       <geometry>
       	   <mesh filename="./meshes/digit_v1_fingertip_pad.obj"/>
       </geometry>
       <material name="blue">
          <color rgba="0 0 1 1" />
       </material>
    </visual>
    <collision>
    	<geometry>
            <mesh filename="./meshes/digit_v1_fingertip_pad.obj"/>
      </geometry>
    </collision>
    <inertial>
      <mass value="0.0168"/>
      <!-- <origin rpy="0 0 0" xyz="0 0 0"/> -->
      <origin rpy="0 0 0" xyz="0 0 0"/>
      <inertia ixx="9.68e-07" ixy="0" ixz="0" iyy="9.68e-07" iyz="0" izz="9.68e-07"/>
    </inertial>
  </link>
  <joint name="joint_15.0_digit_fingertip" type="fixed">
    <parent link="link_15.0_tip"/>
    <child link="digit_fingertip_15.0"/>
    <origin rpy="0 0 0" xyz="0.0005 -0.009 0.0"/>
  </joint>

  
  <link name="reskin_link_14.0">
    <!-- <visual>
      <geometry>
        <mesh filename="./meshes/reskin_finger_pad.obj" scale="0.001 0.001 0.001"/>
      </geometry>
      <origin rpy="-1.5707963259 0 -1.5707963259" xyz="0 0 0"/>
      <material name="grey">
        <color rgba="0.4 0.4 0.4 1"/>
      </material>
    </visual> -->
    <!--<collision>
      <geometry>
        <mesh filename="./meshes/reskin_finger_pad.obj" scale="0.001 0.001 0.03"/>
      </geometry>
      <origin rpy="-1.5707963259 0 -1.5707963259" xyz="0 0 0"/>
    </collision> -->
  </link>
  <joint name="reskin_joint_14" type="fixed">
    <parent link="link_14.0"/>
    <child link="reskin_link_14.0"/>
    <origin rpy="0 0 0" xyz="0.0118 0.009 0.022"/>
  </joint>
  <link name="reskin_link_15.0">
    <!-- <visual>
      <geometry>
        <mesh filename="./meshes/reskin_finger_pad.obj" scale="0.001 0.001 0.001"/>
      </geometry>
      <origin rpy="-1.5707963259 0 -1.5707963259" xyz="0 0 0"/>
      <material name="grey">
        <color rgba="0.4 0.4 0.4 1"/>
      </material>
    </visual> -->
    <!-- <collision>
     <geometry>
        <mesh filename="./meshes/reskin_finger_pad.obj" scale="0.001 0.001 0.03"/>
      </geometry>
      <origin rpy="-1.5707963259 0 -1.5707963259" xyz="0 0 0"/>
      </collision> -->
  </link>
  <joint name="reskin_joint_15" type="fixed">
    <parent link="link_15.0"/>
    <child link="reskin_link_15.0"/>
    <origin rpy="0 0 0" xyz="0.0118 0.009 0.022"/>
  </joint>
</robot>

